promise.then(f1).catch(f2);//error in f1 catches in .catch


promise.then(f1, f2);//error is not handled